<?xml version="1.0" encoding="UTF-8"?>
<!-- Generated by org.testng.reporters.JUnitReportReporter -->
<testsuite hostname="DESKTOP-ITJ9AKB" failures="1" tests="5" name="TestScripts.googlepagetest_new" time="25.230" errors="0" timestamp="2025-07-09T22:57:21 IST" skipped="2">
  <testcase classname="TestScripts.googlepagetest_new" name="display2" time="2.854">
    <failure message="expected [2] but found [1]" type="java.lang.AssertionError">
      <![CDATA[java.lang.AssertionError: expected [2] but found [1]
at org.testng.Assert.fail(Assert.java:110)
at org.testng.Assert.failNotEquals(Assert.java:1413)
at org.testng.Assert.assertEqualsImpl(Assert.java:149)
at org.testng.Assert.assertEquals(Assert.java:131)
at org.testng.Assert.assertEquals(Assert.java:1240)
at org.testng.Assert.assertEquals(Assert.java:1274)
at TestScripts.googlepagetest_new.display2(googlepagetest_new.java:31)
at java.base/jdk.internal.reflect.DirectMethodHandleAccessor.invoke(Unknown Source)
at java.base/java.lang.reflect.Method.invoke(Unknown Source)
at org.testng.internal.invokers.MethodInvocationHelper.invokeMethod(MethodInvocationHelper.java:136)
at org.testng.internal.invokers.TestInvoker.invokeMethod(TestInvoker.java:658)
at org.testng.internal.invokers.TestInvoker.retryFailed(TestInvoker.java:261)
at org.testng.internal.invokers.MethodRunner.runInSequence(MethodRunner.java:62)
at org.testng.internal.invokers.TestInvoker$MethodInvocationAgent.invoke(TestInvoker.java:923)
at org.testng.internal.invokers.TestInvoker.invokeTestMethods(TestInvoker.java:192)
at org.testng.internal.invokers.TestMethodWorker.invokeTestMethods(TestMethodWorker.java:146)
at org.testng.internal.invokers.TestMethodWorker.run(TestMethodWorker.java:128)
at java.base/java.util.ArrayList.forEach(Unknown Source)
at org.testng.TestRunner.privateRun(TestRunner.java:808)
at org.testng.TestRunner.run(TestRunner.java:603)
at org.testng.SuiteRunner.runTest(SuiteRunner.java:429)
at org.testng.SuiteRunner.access$000(SuiteRunner.java:32)
at org.testng.SuiteRunner$SuiteWorker.run(SuiteRunner.java:467)
at org.testng.internal.thread.ThreadUtil.lambda$execute$0(ThreadUtil.java:58)
at java.base/java.util.concurrent.FutureTask.run(Unknown Source)
at java.base/java.util.concurrent.ThreadPoolExecutor.runWorker(Unknown Source)
at java.base/java.util.concurrent.ThreadPoolExecutor$Worker.run(Unknown Source)
at java.base/java.lang.Thread.run(Unknown Source)
]]>
    </failure>
  </testcase> <!-- display2 -->
  <system-out/>
  <testcase classname="TestScripts.googlepagetest_new" name="display1" time="3.026"/>
  <system-out/>
  <testcase classname="TestScripts.googlepagetest_new" name="display2" time="2.973">
    <skipped/>
  </testcase> <!-- display2 -->
  <system-out/>
  <testcase classname="TestScripts.googlepagetest_new" name="display2" time="3.045">
    <skipped/>
  </testcase> <!-- display2 -->
  <system-out/>
  <testcase classname="TestScripts.googlepagetest_new" name="openurl" time="13.332"/>
  <system-out/>
</testsuite> <!-- TestScripts.googlepagetest_new -->
